<?xml version="1.0" encoding="utf-8"?>
<!-- This URDF was automatically created by SolidWorks to URDF Exporter! Originally created by Stephen Brawner (brawner@gmail.com)
     Commit Version: 1.6.0-1-g15f4949  Build Version: 1.6.7594.29634
     For more information, please see http://wiki.ros.org/sw_urdf_exporter -->
<robot
  name="Assem_fnl">

  <gazebo>
    <plugin name="gazebo_ros_control" filename="libgazebo_ros_control.so">
      <robotNamespace></robotNamespace>
      <robotSimType>gazebo_ros_control/DefaultRobotHWSim</robotSimType>
      <legacyModeNS>true</legacyModeNS>
    </plugin>
  </gazebo>
<!--
  <gazebo>
    <plugin name="MimicJointPlugin" filename="libroboticsgroup_gazebo_mimic_joint_plugin.so">
      <joint>claw_part_3_joint</joint>
      <mimicJoint>claw_1_joint</mimicJoint>
    </plugin>
  </gazebo>
-->
<!--
 <gazebo>
     <plugin name="Myrobot_ClosedLoopPlugin" filename="libpegasus_gazebo_closed_loop_plugin.so">
         <joint>plate_gripper_joint</joint>
         <child>claw_1_link</child>
         <parent>claw_part_3_link</parent>
         <position>0.0 0.0 0.0</position>
         <rotation>0.00 -0.00 0.00</rotation>
     </plugin>
 </gazebo>
-->

  <link
    name="base_link">
    <inertial>
      <origin
        xyz="0.000245228555021293 -0.000485601868001451 0.0326909146616174"
        rpy="0 0 0" />
      <mass
        value="50.6467934"/>
      <inertia
        ixx="0.487436962309936"
        ixy="-1.41855005569046E-05"
        ixz="0.000115722726747853"
        iyy="0.884389812574198"
        iyz="-0.000233043409626158"
        izz="1.30737819360333" />
    </inertial>
    <visual>
      <origin
        xyz="0 0 0"
        rpy="0 0 0" />
      <geometry>
        <mesh
          filename="package://Assem_fnl/meshes/visual/base_link.STL" />
      </geometry>
      <material
        name="">
        <color
          rgba="0.792156862745098 0.819607843137255 0.933333333333333 1" />
      </material>
    </visual>
    <collision>
      <origin
        xyz="0 0 0"
        rpy="0 0 0" />
      <geometry>
        <mesh
          filename="package://Assem_fnl/meshes/collision/base_link.stl" />
      </geometry>
    </collision>
  </link>
  <link
    name="link_sh1_1">
    <inertial>
      <origin
        xyz="3.60822483003176E-16 0.0266401832789713 2.77555756156289E-17"
        rpy="0 0 0" />
      <mass
        value="1.88910976344759" />
      <inertia
        ixx="0.00815057397058659"
        ixy="2.36548102133572E-17"
        ixz="0"
        iyy="0.00055983034329253"
        iyz="3.14474323677546E-18"
        izz="0.00815057397058659" />
    </inertial>
    <visual>
      <origin
        xyz="0 0 0"
        rpy="0 0 0" />
      <geometry>
        <mesh
          filename="package://Assem_fnl/meshes/visual/link_sh1_1.STL" />
      </geometry>
      <material
        name="">
        <color
          rgba="0.647058823529412 0.619607843137255 0.584313725490196 1" />
      </material>
    </visual>
    <collision>
      <origin
        xyz="0 0 0"
        rpy="0 0 0" />
      <geometry>
        <mesh
          filename="package://Assem_fnl/meshes/collision/link_sh1_1.stl" />
      </geometry>
    </collision>
  </link>
  <joint
    name="joint_sh1_1"
    type="revolute">
    <origin
      xyz="0.246 0.1631 0.053"
      rpy="0 0.61414 0" />
    <parent
      link="base_link" />
    <child
      link="link_sh1_1" />
    <axis
      xyz="0 1 0" />
    <limit
      lower="0"
      upper="6.283"
      effort="0"
      velocity="0" />
      <!-- forward +ve -->

  </joint>
  <link
    name="link_t1_1">
    <inertial>
      <origin
        xyz="0 -0.0437281587639727 3.46944695195361E-18"
        rpy="0 0 0" />
      <mass
        value="7" />
      <inertia
        ixx="0.90"
        ixy="0.97"
        ixz="0.78"
        iyx="0.97"
        iyy="2.19"
        iyz="0.42"
        izx="0.78"
        izy="0.42"
        izz="2.41" />
    </inertial>
    <visual>
      <origin
        xyz="0 0 0"
        rpy="0 0 0" />
      <geometry>
        <mesh
          filename="package://Assem_fnl/meshes/visual/link_t1_1.STL" />
      </geometry>
      <material
        name="">
        <color
          rgba="0.792156862745098 0.819607843137255 0.933333333333333 1" />
      </material>
    </visual>
    <collision>
      <origin
        xyz="0 0 0"
        rpy="0 0 0" />
      <geometry>
        <mesh
          filename="package://Assem_fnl/meshes/collision/link_t1_1.stl" />
      </geometry>
    </collision>
  </link>
  <joint
    name="joint_t1_1"
    type="fixed">
    <origin
      xyz="0 0.047 0"
      rpy="3.1416 -1.3284 0" />
    <parent
      link="link_sh1_1" />
    <child
      link="link_t1_1" />
    <axis
      xyz="0 0 0" />
    <limit
      lower="0"
      upper="0"
      effort="0"
      velocity="0" />
    <dynamics
      friction= "1000" />
  </joint>
  <link
    name="link_sh1_2">
    <inertial>
      <origin
        xyz="3.81639164714898E-16 0.0266401832789712 0"
        rpy="0 0 0" />
      <mass
        value="1.88910976344759" />
      <inertia
        ixx="0.00815057397058659"
        ixy="2.3314941049737E-17"
        ixz="0"
        iyy="0.00055983034329253"
        iyz="2.99631939640779E-18"
        izz="0.00815057397058659" />
    </inertial>
    <visual>
      <origin
        xyz="0 0 0"
        rpy="0 0 0" />
      <geometry>
        <mesh
          filename="package://Assem_fnl/meshes/visual/link_sh1_2.STL" />
      </geometry>
      <material
        name="">
        <color
          rgba="0.647058823529412 0.619607843137255 0.584313725490196 1" />
      </material>
    </visual>
    <collision>
      <origin
        xyz="0 0 0"
        rpy="0 0 0" />
      <geometry>
        <mesh
          filename="package://Assem_fnl/meshes/collision/link_sh1_2.stl" />
      </geometry>
    </collision>
  </link>
  <joint
    name="joint_sh1_2"
    type="revolute">
    <origin
      xyz="0.246 -0.163 0.053"
      rpy="0 -0.37309 3.1416" />
    <parent
      link="base_link" />
    <child
      link="link_sh1_2" />
    <axis
      xyz="0 1 0" />
    <limit
      lower="0"
      upper="6.283"
      effort="10"
      velocity="2" />
      <!--forward at negative -->
  </joint>
  <link
    name="link_t1_2">
    <inertial>
      <origin
        xyz="-6.93889390390723E-18 -0.0437281587639726 0"
        rpy="0 0 0" />
      <mass
        value="7" />
      <inertia
        ixx="1.01"
        ixy="0.01"
        ixz="0"
        iyx="0.01"
        iyy="0.21"
        iyz="0.00"
        izx="0"
        izy="0.00"
        izz="1.15" />
    </inertial>
    <visual>
      <origin
        xyz="0 0 0"
        rpy="0 0 0" />
      <geometry>
        <mesh
          filename="package://Assem_fnl/meshes/visual/link_t1_2.STL" />
      </geometry>
      <material
        name="">
        <color
          rgba="0.792156862745098 0.819607843137255 0.933333333333333 1" />
      </material>
    </visual>
    <collision>
      <origin
        xyz="0 0 0"
        rpy="0 0 0" />
      <geometry>
        <mesh
          filename="package://Assem_fnl/meshes/collision/link_t1_2.stl" />
      </geometry>
    </collision>
  </link>
  <joint
    name="joint_t1_2"
    type="fixed">
    <origin
      xyz="0 0.047 0"
      rpy="0 0.6334 3.1416" />
    <parent
      link="link_sh1_2" />
    <child
      link="link_t1_2" />
    <axis
      xyz="0 0 0" />
    <limit
      lower="0"
      upper="0"
      effort="0"
      velocity="0" />
    <dynamics
      friction ="1000" />
  </joint>
  <link
    name="link_sh2_1">
    <inertial>
      <origin
        xyz="4.44089209850063E-16 0.00429143099730334 -1.11022302462516E-16"
        rpy="0 0 0" />
      <mass
        value="1.91717027267991" />
      <inertia
        ixx="0.00832905389350432"
        ixy="-7.8383224326297E-19"
        ixz="0"
        iyy="0.00056061954511469"
        iyz="1.47358871394239E-19"
        izz="0.00832905389350432" />
    </inertial>
    <visual>
      <origin
        xyz="0 0 0"
        rpy="0 0 0" />
      <geometry>
        <mesh
          filename="package://Assem_fnl/meshes/visual/link_sh2_1.STL" />
      </geometry>
      <material
        name="">
        <color
          rgba="0.647058823529412 0.619607843137255 0.584313725490196 1" />
      </material>
    </visual>
    <collision>
      <origin
        xyz="0 0 0"
        rpy="0 0 0" />
      <geometry>
        <mesh
          filename="package://Assem_fnl/meshes/collision/link_sh2_1.stl" />
      </geometry>
    </collision>
  </link>
  <joint
    name="joint_sh2_1"
    type="revolute">
    <origin
      xyz="-0.246 0.127 0.053"
      rpy="3.1416 1.0385 3.1416" />
    <parent
      link="base_link" />
    <child
      link="link_sh2_1" />
    <axis
      xyz="0 1 0" />
    <limit
      lower="0"
      upper="6.283"
      effort="0"
      velocity="0" />

  </joint>
  <link
    name="link_t2_1">
    <inertial>
      <origin
        xyz="-1.11022302462516E-16 -0.0437281587639727 2.77555756156289E-17"
        rpy="0 0 0" />
      <mass
        value="7" />
      <inertia
        ixx="0.90"
        ixy="0.03"
        ixz="0.03"
        iyx="0.03"
        iyy="0.38"
        iyz="0.42"
        izx="0.03"
        izy="0.42"
        izz="0.60"  />
    </inertial>
    <visual>
      <origin
        xyz="0 0 0"
        rpy="0 0 0" />
      <geometry>
        <mesh
          filename="package://Assem_fnl/meshes/visual/link_t2_1.STL" />
      </geometry>
      <material
        name="">
        <color
          rgba="0.792156862745098 0.819607843137255 0.933333333333333 1" />
      </material>
    </visual>
    <collision>
      <origin
        xyz="0 0 0"
        rpy="0 0 0" />
      <geometry>
        <mesh
          filename="package://Assem_fnl/meshes/collision/link_t2_1.stl" />
      </geometry>
    </collision>
  </link>
  <joint
    name="joint_t2_1"
    type="fixed">
    <origin
      xyz="0 0.083 0"
      rpy="3.1416 -0.37818 0" />
    <parent
      link="link_sh2_1" />
    <child
      link="link_t2_1" />
    <axis
      xyz="0 0 0" />
    <limit
      lower="0"
      upper="0"
      effort="0"
      velocity="0" />
    <dynamics
      friction ="1000" />
  </joint>
  <link
    name="link_sh2_2">
    <inertial>
      <origin
        xyz="3.33066907387547E-16 0.00429143099730334 -5.55111512312578E-17"
        rpy="0 0 0" />
      <mass
        value="1.91717027267991" />
      <inertia
        ixx="0.00832905389350432"
        ixy="-1.02531408348597E-18"
        ixz="0"
        iyy="0.00056061954511469"
        iyz="-8.7774241875515E-22"
        izz="0.00832905389350432" />
    </inertial>
    <visual>
      <origin
        xyz="0 0 0"
        rpy="0 0 0" />
      <geometry>
        <mesh
          filename="package://Assem_fnl/meshes/visual/link_sh2_2.STL" />
      </geometry>
      <material
        name="">
        <color
          rgba="0.647058823529412 0.619607843137255 0.584313725490196 1" />
      </material>
    </visual>
    <collision>
      <origin
        xyz="0 0 0"
        rpy="0 0 0" />
      <geometry>
        <mesh
          filename="package://Assem_fnl/meshes/collision/link_sh2_2.stl" />
      </geometry>
    </collision>
  </link>
  <joint
    name="joint_sh2_2"
    type="revolute">
    <origin
      xyz="-0.246 -0.127 0.053"
      rpy="0 -0.080442 3.1416" />
    <parent
      link="base_link" />
    <child
      link="link_sh2_2" />
    <axis
      xyz="0 1 0" />
    <limit
      lower="0"
      upper="6.283"
      effort="0"
      velocity="0" />

  </joint>
  <link
    name="link_t2_2">
    <inertial>
      <origin
        xyz="-5.55111512312578E-17 -0.0437281587639727 -1.11022302462516E-16"
        rpy="0 0 0" />
      <mass
        value="7" />
      <inertia
        ixx="4.25"
        ixy="0.03"
        ixz="0.09"
        iyx="0.03"
        iyy="3.74"
        iyz="1.38"
        izx="0.09"
        izy="1.38"
        izz="0.60" />
    </inertial>
    <visual>
      <origin
        xyz="0 0 0"
        rpy="0 0 0" />
      <geometry>
        <mesh
          filename="package://Assem_fnl/meshes/visual/link_t2_2.STL" />
      </geometry>
      <material
        name="">
        <color
          rgba="0.792156862745098 0.819607843137255 0.933333333333333 1" />
      </material>
    </visual>
    <collision>
      <origin
        xyz="0 0 0"
        rpy="0 0 0" />
      <geometry>
        <mesh
          filename="package://Assem_fnl/meshes/collision/link_t2_2.stl" />
      </geometry>
    </collision>
  </link>
  <joint
    name="joint_t2_2"
    type="fixed">
    <origin
      xyz="0 0.083 0"
      rpy="0 -0.14131 3.1416" />
    <parent
      link="link_sh2_2" />
    <child
      link="link_t2_2" />
    <axis
      xyz="0 0 0" />
    <limit
      lower="0"
      upper="0"
      effort="0"
      velocity="0" />
    <dynamics
      friction ="1000" />

  </joint>
  <link
    name="link_Msh_1">
    <inertial>
      <origin
        xyz="-1.16573417585641E-15 -0.00188400148089063 -1.11022302462516E-16"
        rpy="0 0 0" />
      <mass
        value="1.28736459459753" />
      <inertia
        ixx="0.00141991589660242"
        ixy="2.07057765245373E-17"
        ixz="-1.62630325872826E-19"
        iyy="0.00045732350572063"
        iyz="2.53242925407615E-18"
        izz="0.00141991589660242" />
    </inertial>
    <visual>
      <origin
        xyz="0 0 0"
        rpy="0 0 0" />
      <geometry>
        <mesh
          filename="package://Assem_fnl/meshes/visual/link_Msh_1.STL" />
      </geometry>
      <material
        name="">
        <color
          rgba="0.647058823529412 0.619607843137255 0.584313725490196 1" />
      </material>
    </visual>
    <collision>
      <origin
        xyz="0 0 0"
        rpy="0 0 0" />
      <geometry>
        <mesh
          filename="package://Assem_fnl/meshes/collision/link_Msh_1.stl" />
      </geometry>
    </collision>
  </link>
  <joint
    name="joint_Msh_1"
    type="revolute">
    <origin
      xyz="0 0.152 0.085"
      rpy="3.1416 -0.48321 0" />
    <parent
      link="base_link" />
    <child
      link="link_Msh_1" />
    <axis
      xyz="0 1 0" />
    <limit
      lower="0"
      upper="0"
      effort="0"
      velocity="0" />
  </joint>
  <link
    name="link_Msh_2">
    <inertial>
      <origin
        xyz="-1.11022302462516E-15 -0.00188400148089063 -1.66533453693773E-16"
        rpy="0 0 0" />
      <mass
        value="1.28736459459753" />
      <inertia
        ixx="0.00141991589660242"
        ixy="2.07278499044851E-17"
        ixz="-1.52465930505774E-19"
        iyy="0.000457323505720631"
        iyz="2.57968883021634E-18"
        izz="0.00141991589660242" />
    </inertial>
    <visual>
      <origin
        xyz="0 0 0"
        rpy="0 0 0" />
      <geometry>
        <mesh
          filename="package://Assem_fnl/meshes/visual/link_Msh_2.STL" />
      </geometry>
      <material
        name="">
        <color
          rgba="0.647058823529412 0.619607843137255 0.584313725490196 1" />
      </material>
    </visual>
    <collision>
      <origin
        xyz="0 0 0"
        rpy="0 0 0" />
      <geometry>
        <mesh
          filename="package://Assem_fnl/meshes/collision/link_Msh_2.stl" />
      </geometry>
    </collision>
  </link>
  <joint
    name="joint_Msh_2"
    type="revolute">
    <origin
      xyz="0 -0.152 0.085"
      rpy="0 -0.02542 0" />
    <parent
      link="base_link" />
    <child
      link="link_Msh_2" />
    <axis
      xyz="0 1 0" />
    <limit
      lower="0"
      upper="0"
      effort="0"
      velocity="0" />
  </joint>
  <link
  name="motorkooper_link">
  <inertial>
    <origin
      xyz="-0.00120545300454244 -0.000461143822939658 0.233638316473452"
      rpy="0 0 0" />
    <mass
      value="17.38"  />
    <inertia
      ixx="1.01"
      ixy="0.01"
      ixz="0.00"
      iyx="0.01"
      iyy="0.21"
      iyz="0.00"
      izz="1.15" />
  </inertial>
  <visual>
    <origin
      xyz="0 0 0"
      rpy="0 0 0" />
    <geometry>
      <mesh
        filename="package://Assem_fnl/meshes/visual/motorkooper_link.STL" />
    </geometry>
    <material
      name="">
      <color
        rgba="0.792156862745098 0.819607843137255 0.933333333333333 1" />
    </material>
  </visual>
  <collision>
    <origin
      xyz="0 0 0"
      rpy="0 0 0" />
    <geometry>
      <mesh
        filename="package://Assem_fnl/meshes/collision/motorkooper_link.stl" />
    </geometry>
  </collision>
</link>
<joint
  name="motorkooper_joint"
  type="fixed">
  <origin
    xyz="-0.26 0.47 -0.22"
    rpy="1.5707 0 0" />
  <parent
    link="base_link" />
  <child
    link="motorkooper_link" />
  <axis
    xyz="0 0 0" />
  </joint>
  <link
    name="rod_wth_cylin_link">
    <inertial>
      <origin
        xyz="-0.0244108175794428 -0.012 0.159055527397006"
        rpy="0 0 0" />
      <mass
        value="4.71123767266371" />
      <inertia
        ixx="0.151060078726739"
        ixy="3.46732936958548E-18"
        ixz="-0.0154520234909176"
        iyy="0.15770726800881"
        iyz="5.13063738019691E-18"
        izz="0.0119981780843595" />
    </inertial>
    <visual>
      <origin
        xyz="0 0 0"
        rpy="0 0 0" />
      <geometry>
        <mesh
          filename="package://Assem_fnl/meshes/visual/rod_wth_cylin_link.STL" />
      </geometry>
      <material
        name="">
        <color
          rgba="0.792156862745098 0.819607843137255 0.933333333333333 1" />
      </material>
    </visual>
    <collision>
      <origin
        xyz="0 0 0"
        rpy="0 0 0" />
      <geometry>
        <mesh
          filename="package://Assem_fnl/meshes/collision/rod_wth_cylin_link.stl" />
      </geometry>
    </collision>
  </link>
  <joint
    name="rod_wth_cylin_joint"
    type="revolute">
    <origin
      xyz="0.264 0.618 0.469"
      rpy="-1.5707 0 0" />
    <parent
      link="motorkooper_link" />
    <child
      link="rod_wth_cylin_link" />
    <axis
      xyz="0 -1 0" />
    <limit
      lower="-1.5707"
      upper="0"
      effort="450"
      velocity="5" />
    <dynamics
      friction="100"
      damping="10" />
  </joint>
  <link
    name="dual_redrod_link">
    <inertial>
      <origin
        xyz="-0.285925121637021 0.00708701348815782 0.000547426734640588"
        rpy="0 0 0" />
      <mass
        value="4.96083086557093" />
      <inertia
        ixx="0.00516246254163912"
        ixy="5.51906715867348E-06"
        ixz="0.0123762688360278"
        iyy="0.205745932268244"
        iyz="-7.65215364696908E-07"
        izz="0.205914461908583" />
    </inertial>
    <visual>
      <origin
        xyz="0 0 0"
        rpy="0 0 0" />
      <geometry>
        <mesh
          filename="package://Assem_fnl/meshes/visual/dual_redrod_link.STL" />
      </geometry>
      <material
        name="">
        <color
          rgba="0.792156862745098 0.819607843137255 0.933333333333333 1" />
      </material>
    </visual>
    <collision>
      <origin
        xyz="0 0 0"
        rpy="0 0 0" />
      <geometry>
        <mesh
          filename="package://Assem_fnl/meshes/collision/dual_redrod_link.stl" />
      </geometry>
    </collision>
  </link>
  <joint
    name="dual_redrod_joint"
    type="revolute">
    <origin
      xyz="0.083 -0.003 0.576"
      rpy="0 0 0" />
    <parent
      link="rod_wth_cylin_link" />
    <child
      link="dual_redrod_link" />
    <axis
      xyz="0 1 0" />
    <limit
      lower="-1.5707"
      upper="0.872"
      effort="450"
      velocity="50" />
    <dynamics
      friction="100"
      damping ="10" />
  </joint>
  <link
    name="struct_over_dual_link">
    <inertial>
      <origin
        xyz="-0.12660154538717 -0.0749819442965102 -0.0130685587306965"
        rpy="0 0 0" />
      <mass
        value="10.5541936012649" />
      <inertia
        ixx="0.034593017975491"
        ixy="-4.12202992454498E-05"
        ixz="0.00203404927446369"
        iyy="0.446025462173523"
        iyz="3.23643700805756E-06"
        izz="0.475530168467849" />
    </inertial>
    <visual>
      <origin
        xyz="0 0 0"
        rpy="0 0 0" />
      <geometry>
        <mesh
          filename="package://Assem_fnl/meshes/visual/struct_over_dual_link.STL" />
      </geometry>
      <material
        name="">
        <color
          rgba="0.792156862745098 0.819607843137255 0.933333333333333 1" />
      </material>
    </visual>
    <collision>
      <origin
        xyz="0 0 0"
        rpy="0 0 0" />
      <geometry>
        <mesh
          filename="package://Assem_fnl/meshes/collision/struct_over_dual_link.stl" />
      </geometry>
    </collision>
  </link>
  <joint
    name="struct_over_dual_joint"
    type="fixed">
    <origin
      xyz="0.55 0.077 0.064"
      rpy="0 0 0" />
    <parent
      link="dual_redrod_link" />
    <child
      link="struct_over_dual_link" />
    <axis
      xyz="0 0 0" />
  </joint>

  <link
    name="sub_claw_part_1_link">
    <inertial>
      <origin
        xyz="-0.120154614612147 0.106923881554251 0.0149999999999999"
        rpy="0 0 0" />
      <mass
        value="2.2286648229313" />
      <inertia
        ixx="0.00474450554529489"
        ixy="-9.64460830501308E-18"
        ixz="-8.27206601008833E-18"
        iyy="0.0176232139105464"
        iyz="1.61353159007044E-18"
        izz="0.0211883448190484" />
    </inertial>
    <visual>
      <origin
        xyz="0 0 0"
        rpy="0 0 0" />
      <geometry>
        <mesh
          filename="package://Assem_fnl/meshes/visual/sub_claw_part_1_link.STL" />
      </geometry>
      <material
        name="">
        <color
          rgba="0.792156862745098 0.819607843137255 0.933333333333333 1" />
      </material>
    </visual>
    <collision>
      <origin
        xyz="0 0 0"
        rpy="0 0 0" />
      <geometry>
        <mesh
          filename="package://Assem_fnl/meshes/collision/sub_claw_part_1_link.stl" />
      </geometry>
    </collision>
  </link>
  <joint
    name="sub_claw_part_1_joint"
    type="revolute">
    <origin
      xyz="0.2715 -0.075 -0.015"
      rpy="0 0 0" />
    <parent
      link="struct_over_dual_link" />
    <child
      link="sub_claw_part_1_link" />
    <axis
      xyz="1 0 0" />
    <limit
      lower="0"
      upper="6.283"
      effort="10"
      velocity="2" />
  </joint>

  <link
  name="claw_part_2_2_link">
  <inertial>
    <origin
      xyz="-0.177150603741962 -0.0149999049377803 -1.14911758997138E-07"
      rpy="0 0 0" />
    <mass
      value="1.48172924497085" />
    <inertia
      ixx="0.00149362963443841"
      ixy="1.84684922214377E-08"
      ixz="-2.69312585031865E-08"
      iyy="0.0349934185815546"
      iyz="-2.37436554810784E-09"
      izz="0.0356299058432863" />
  </inertial>
  <visual>
    <origin
      xyz="0 0 0"
      rpy="0 0 0" />
    <geometry>
      <mesh
        filename="package://Assem_fnl/meshes/visual/claw_part_2_2_link.STL" />
    </geometry>
    <material
      name="">
      <color
        rgba="0.792156862745098 0.819607843137255 0.933333333333333 1" />
    </material>
  </visual>
  <collision>
    <origin
      xyz="0 0 0"
      rpy="0 0 0" />
    <geometry>
      <mesh
        filename="package://Assem_fnl/meshes/collision/claw_part_2_2_link.stl" />
    </geometry>
  </collision>
</link>
<joint
  name="claw_part_2_2_joint"
  type="prismatic">
  <origin
    xyz="-0.013 0 0"
    rpy="0 0 0" />
  <parent
    link="sub_claw_part_1_link" />
  <child
    link="claw_part_2_2_link" />
  <axis
    xyz="1 0 0" />
  <limit
    lower="-0.05"
    upper="0.05"
    effort="0"
    velocity="0" />
</joint>

  <link
  name="claw_1_link">
  <inertial>
    <origin
      xyz="-0.0685036800834815 0.0410807887941437 0.0149999999999997"
      rpy="0 0 0" />
    <mass
      value="3.76611840248057" />
    <inertia
      ixx="0.00648721569485819"
      ixy="-0.00484931338159159"
      ixz="-9.05152921499203E-18"
      iyy="0.027371208605494"
      iyz="-4.27670905535636E-18"
      izz="0.0319709511637982" />
  </inertial>
  <visual>
    <origin
      xyz="0 0 0"
      rpy="0 0 0" />
    <geometry>
      <mesh
        filename="package://Assem_fnl/meshes/visual/claw_1_link.STL" />
    </geometry>
    <material
      name="">
      <color
        rgba="0.792156862745098 0.819607843137255 0.933333333333333 1" />
    </material>
  </visual>
  <collision>
    <origin
      xyz="0 0 0"
      rpy="0 0 0" />
    <geometry>
      <mesh
        filename="package://Assem_fnl/meshes/collision/claw_1_link.stl" />
    </geometry>
  </collision>
</link>
<joint
  name="claw_1_joint"
  type="revolute">
  <origin
    xyz="0.158 -0.1065 0"
    rpy="0 0 0.261" />
  <parent
    link="sub_claw_part_1_link" />
  <child
    link="claw_1_link" />
  <axis
    xyz="0 0 1" />
  <limit
    lower="-0.29"
    upper="0"
    effort="10"
    velocity="5" />
    <!-- lower minus -->
</joint>


<link
name="claw_2_link">
<inertial>
  <origin
    xyz="-0.0685036800834813 0.0410807887941437 0.0149999999999999"
    rpy="0 0 0" />
  <mass
    value="3.76611840248056" />
  <inertia
    ixx="0.00648721569485816"
    ixy="-0.0048493133815916"
    ixz="-4.07757245731701E-18"
    iyy="0.027371208605494"
    iyz="-6.67090062032985E-18"
    izz="0.0319709511637982" />
</inertial>
<visual>
  <origin
    xyz="0 0 0"
    rpy="0 0 0" />
  <geometry>
    <mesh
      filename="package://Assem_fnl/meshes/visual/claw_2_link.STL" />
  </geometry>
  <material
    name="">
    <color
      rgba="0.792156862745098 0.819607843137255 0.933333333333333 1" />
  </material>
</visual>
<collision>
  <origin
    xyz="0 0 0"
    rpy="0 0 0" />
  <geometry>
    <mesh
      filename="package://Assem_fnl/meshes/collision/claw_2_link.stl" />
  </geometry>
</collision>
</link>
<joint
name="claw_2_joint"
type="revolute">
<origin
  xyz="0.158 0.1065 0"
  rpy="3.14 0 -0.261" />
<parent
  link="sub_claw_part_1_link" />
<child
  link="claw_2_link" />
<axis
  xyz="0 0 1" />
<limit
  lower="-0.29"
  upper="0"
  effort="10"
  velocity="5" />
</joint>

<!-- ################################################# PROPERTIES ############################################### -->
<gazebo reference="claw_1_link">
  <kp>100000.0</kp>
  <kd>1.0</kd>
  <mu1>10000.0</mu1>
  <mu2>10000</mu2>
  <fdir1>1 0 0</fdir1>
  <minDepth>0.01</minDepth>
</gazebo>

<gazebo reference="claw_2_link">
  <kp>100000.0</kp>
  <kd>1.0</kd>
  <mu1>20000.0</mu1>
  <mu2>20000</mu2>
  <fdir1>1 0 0</fdir1>
  <minDepth>0.01</minDepth>
</gazebo>

<gazebo reference="link_t1_1">
  <mu1>30000.0</mu1>
  <mu2>30000</mu2>
  <fdir1>0 1 0</fdir1>
  <minDepth>0.02</minDepth>
</gazebo>

<gazebo reference="link_t1_2">
  <mu1>30000.0</mu1>
  <mu2>30000</mu2>
  <fdir1>0 1 0</fdir1>
  <minDepth>0.02</minDepth>
</gazebo>

<gazebo reference="link_t2_1">
  <mu1>30000.0</mu1>
  <mu2>30000</mu2>
  <fdir1>0 1 0</fdir1>
  <minDepth>0.02</minDepth>
</gazebo>

<gazebo reference="link_t2_2">
  <mu1>30000.0</mu1>
  <mu2>30000</mu2>
  <fdir1>0 1 0</fdir1>
  <minDepth>0.02</minDepth>
</gazebo>

<gazebo>
  <gripper name="grasping">
    <grasp_check>
        <attach_steps>5</attach_steps>
        <detach_steps>10</detach_steps>
        <min_contact_count>1</min_contact_count>
    </grasp_check>
    <gripper_link>claw_1_link</gripper_link>
    <palm_link>claw_2_link</palm_link>
  </gripper>
</gazebo>
<!--########################################## SENSORS ###################################-->

  <!-- Hokuyo Laser -->

<!--
<link
name="Dummy_plate_link">
<inertial>
  <origin
    xyz="-0.0685036800834816 0.0410807887941436 0.0149999999999999"
    rpy="0 0 0" />
  <mass
    value="1" />
  <inertia
    ixx="0.000821166543652936"
    ixy="-0.000613837136910328"
    ixz="-2.35325594742188E-19"
    iyy="0.00346470995006253"
    iyz="-2.01046247881013E-19"
    izz="0.00404695584351876" />
</inertial>
<visual>
  <origin
    xyz="0 0 0"
    rpy="0 0 0" />
  <geometry>
    <mesh
      filename="package://Assem_fnl/meshes/Dummy_plate_link.STL" />
  </geometry>
  <material
    name="">
    <color
      rgba="0.792156862745098 0.819607843137255 0.933333333333333 1" />
  </material>
</visual>
<collision>
  <origin
    xyz="0 0 0"
    rpy="0 0 0" />
  <geometry>
    <mesh
      filename="package://Assem_fnl/meshes/Dummy_plate_link.STL" />
  </geometry>
</collision>
</link>
<joint
name="Dummy_plate_joint"
type="fixed">
<origin
  xyz="0 0 0"
  rpy="0 0 0" />
<parent
  link="claw_part_3_2_link" />
<child
  link="Dummy_plate_link" />
<axis
  xyz="0 0 1" />
<limit
  lower="0"
  upper="0"
  effort="1000"
  velocity="2" />
</joint>
-->
<!--
<gazebo reference="">
  <friction>3</friction>
  <friction2>3</friction2>
  <kp>100000</kp>
  <kd>10000</kd>
  <dampingFactor>6</dampingFactor>
</gazebo>
-->
<!--
<gazebo>
        <joint name='plate_gripper_joint' type='revolute'>
            <child>claw_1_link</child>
            <parent>claw_part_3_link</parent>
            <pose>-0.055 -0.0525 0
              0 0 0 </pose>
            <axis>
                <xyz>0 0 0</xyz>
                <limit>
                  <lower>-3</lower>
                    <upper>3</upper>
                    <effort>1</effort>
                    <velocity>10</velocity>
                </limit>
                <dynamics>
                    <damping>10</damping>
                    <friction>10</friction>
                    <spring_reference>0</spring_reference>
                    <spring_stiffness>0</spring_stiffness>
                </dynamics>
                <use_parent_model_frame>1</use_parent_model_frame>
            </axis>
        </joint>
  </gazebo>

  <gazebo>
          <joint name='plate2_gripper2_joint' type='revolute'>
              <child>claw_2_link</child>
              <parent>claw_part_3_2_link</parent>
              <pose>-0.055 -0.0525 0
                0 0 0</pose>
              <axis>
                  <xyz>0 0 0</xyz>
                  <limit>
                      <lower>3</lower>
                      <upper>-3</upper>
                      <effort>1</effort>
                      <velocity>10</velocity>
                  </limit>
                  <dynamics>
                      <damping>10</damping>
                      <friction>10</friction>
                      <spring_reference>0</spring_reference>
                      <spring_stiffness>0</spring_stiffness>
                  </dynamics>
                  <use_parent_model_frame>1</use_parent_model_frame>
              </axis>
          </joint>
    </gazebo>
-->



  <transmission name="T1">
  <type>transmission_interface/SimpleTransmission</type>
  <joint name="joint_sh1_1">
    <hardwareInterface>hardware_interface/EffortJointInterface</hardwareInterface>
  </joint>
  <actuator name="M1">
    <hardwareInterface>hardware_interface/EffortJointInterface</hardwareInterface>
    <mechanicalReduction>1</mechanicalReduction>
  </actuator>
</transmission>

<transmission name="T2">
<type>transmission_interface/SimpleTransmission</type>
<joint name="joint_sh1_2">
  <hardwareInterface>hardware_interface/EffortJointInterface</hardwareInterface>
</joint>
<actuator name="M2">
  <hardwareInterface>hardware_interface/EffortJointInterface</hardwareInterface>
  <mechanicalReduction>1</mechanicalReduction>
</actuator>
</transmission>

<transmission name="T3">
<type>transmission_interface/SimpleTransmission</type>
<joint name="joint_sh2_1">
  <hardwareInterface>hardware_interface/EffortJointInterface</hardwareInterface>
</joint>
<actuator name="M3">
  <hardwareInterface>hardware_interface/EffortJointInterface</hardwareInterface>
  <mechanicalReduction>1</mechanicalReduction>
</actuator>
</transmission>

<transmission name="T4">
<type>transmission_interface/SimpleTransmission</type>
<joint name="joint_sh2_2">
  <hardwareInterface>hardware_interface/EffortJointInterface</hardwareInterface>
</joint>
<actuator name="M4">
  <hardwareInterface>hardware_interface/EffortJointInterface</hardwareInterface>
  <mechanicalReduction>1</mechanicalReduction>
</actuator>
</transmission>

<transmission name="T5">
<type>transmission_interface/SimpleTransmission</type>
<joint name="rod_wth_cylin_joint">
  <hardwareInterface>hardware_interface/EffortJointInterface</hardwareInterface>
</joint>
<actuator name="M5">
  <hardwareInterface>hardware_interface/EffortJointInterface</hardwareInterface>
  <mechanicalReduction>1</mechanicalReduction>
</actuator>
</transmission>

<transmission name="T6">
<type>transmission_interface/SimpleTransmission</type>
<joint name="dual_redrod_joint">
  <hardwareInterface>hardware_interface/EffortJointInterface</hardwareInterface>
</joint>
<actuator name="M6">
  <hardwareInterface>hardware_interface/EffortJointInterface</hardwareInterface>
  <mechanicalReduction>1</mechanicalReduction>
</actuator>
</transmission>

<transmission name="T7">
<type>transmission_interface/SimpleTransmission</type>
<joint name="sub_claw_part_1_joint">
  <hardwareInterface>hardware_interface/EffortJointInterface</hardwareInterface>
</joint>
<actuator name="M7">
  <hardwareInterface>hardware_interface/EffortJointInterface</hardwareInterface>
  <mechanicalReduction>1</mechanicalReduction>
</actuator>
</transmission>


<transmission name="T8">
<type>transmission_interface/SimpleTransmission</type>
<joint name="claw_2_joint">
  <hardwareInterface>hardware_interface/EffortJointInterface</hardwareInterface>
</joint>
<actuator name="M8">
  <hardwareInterface>hardware_interface/EffortJointInterface</hardwareInterface>
  <mechanicalReduction>1</mechanicalReduction>
</actuator>
</transmission>


<transmission name="T9">
<type>transmission_interface/SimpleTransmission</type>
<joint name="claw_1_joint">
  <hardwareInterface>hardware_interface/EffortJointInterface</hardwareInterface>
</joint>
<actuator name="M9">
  <hardwareInterface>hardware_interface/EffortJointInterface</hardwareInterface>
  <mechanicalReduction>1</mechanicalReduction>
</actuator>
</transmission>



</robot>
